2025-05-02 15:35:43,651 [INFO] USER:SunilKumarPradhan handlers.py:106:syndicate LOG: Configuration used: C:\Users\sunilkumar_pradhan\Desktop\PBE\carrent\backend\.syndicate-config-dev
2025-05-02 15:35:43,652 [ERROR] USER:SunilKumarPradhan decorators.py:136:wrapper LOG: sdct.conf does not exist inside C:\Users\sunilkumar_pradhan\Desktop\PBE\carrent\backend\.syndicate-config-dev folder
2025-05-02 15:35:43,655 [ERROR] USER:SunilKumarPradhan decorators.py:137:wrapper LOG: Traceback (most recent call last):
  File "C:\Users\sunilkumar_pradhan\AppData\Local\Programs\Python\Python313\Lib\site-packages\syndicate\core\decorators.py", line 134, in wrapper
    return_code = func(*args, **kwargs)
  File "C:\Users\sunilkumar_pradhan\AppData\Local\Programs\Python\Python313\Lib\site-packages\syndicate\core\handlers.py", line 107, in syndicate
    initialize_connection()
    ~~~~~~~~~~~~~~~~~~~~~^^
  File "C:\Users\sunilkumar_pradhan\AppData\Local\Programs\Python\Python313\Lib\site-packages\syndicate\core\__init__.py", line 106, in initialize_connection
    CONFIG = ConfigHolder(CONF_PATH)
  File "C:\Users\sunilkumar_pradhan\AppData\Local\Programs\Python\Python313\Lib\site-packages\syndicate\core\conf\processor.py", line 63, in __init__
    self._init_conf_config(dir_path=dir_path)
    ~~~~~~~~~~~~~~~~~~~~~~^^^^^^^^^^^^^^^^^^^
  File "C:\Users\sunilkumar_pradhan\AppData\Local\Programs\Python\Python313\Lib\site-packages\syndicate\core\conf\processor.py", line 92, in _init_conf_config
    raise AssertionError(
        'sdct.conf does not exist inside %s folder' % dir_path)
AssertionError: sdct.conf does not exist inside C:\Users\sunilkumar_pradhan\Desktop\PBE\carrent\backend\.syndicate-config-dev folder
Traceback (most recent call last):
  File "C:\Users\sunilkumar_pradhan\AppData\Local\Programs\Python\Python313\Lib\site-packages\syndicate\core\decorators.py", line 134, in wrapper
    return_code = func(*args, **kwargs)
  File "C:\Users\sunilkumar_pradhan\AppData\Local\Programs\Python\Python313\Lib\site-packages\syndicate\core\handlers.py", line 107, in syndicate
    initialize_connection()
    ~~~~~~~~~~~~~~~~~~~~~^^
  File "C:\Users\sunilkumar_pradhan\AppData\Local\Programs\Python\Python313\Lib\site-packages\syndicate\core\__init__.py", line 106, in initialize_connection
    CONFIG = ConfigHolder(CONF_PATH)
  File "C:\Users\sunilkumar_pradhan\AppData\Local\Programs\Python\Python313\Lib\site-packages\syndicate\core\conf\processor.py", line 63, in __init__
    self._init_conf_config(dir_path=dir_path)
    ~~~~~~~~~~~~~~~~~~~~~~^^^^^^^^^^^^^^^^^^^
  File "C:\Users\sunilkumar_pradhan\AppData\Local\Programs\Python\Python313\Lib\site-packages\syndicate\core\conf\processor.py", line 92, in _init_conf_config
    raise AssertionError(
        'sdct.conf does not exist inside %s folder' % dir_path)
AssertionError: sdct.conf does not exist inside C:\Users\sunilkumar_pradhan\Desktop\PBE\carrent\backend\.syndicate-config-dev folder
2025-05-02 15:36:48,367 [INFO] USER:SunilKumarPradhan handlers.py:106:syndicate LOG: Configuration used: C:\Users\sunilkumar_pradhan\Desktop\PBE\carrent\backend\.syndicate-config-dev
2025-05-02 15:36:48,369 [ERROR] USER:SunilKumarPradhan decorators.py:136:wrapper LOG: sdct.conf does not exist inside C:\Users\sunilkumar_pradhan\Desktop\PBE\carrent\backend\.syndicate-config-dev folder
2025-05-02 15:36:48,372 [ERROR] USER:SunilKumarPradhan decorators.py:137:wrapper LOG: Traceback (most recent call last):
  File "C:\Users\sunilkumar_pradhan\AppData\Local\Programs\Python\Python313\Lib\site-packages\syndicate\core\decorators.py", line 134, in wrapper
    return_code = func(*args, **kwargs)
  File "C:\Users\sunilkumar_pradhan\AppData\Local\Programs\Python\Python313\Lib\site-packages\syndicate\core\handlers.py", line 107, in syndicate
    initialize_connection()
    ~~~~~~~~~~~~~~~~~~~~~^^
  File "C:\Users\sunilkumar_pradhan\AppData\Local\Programs\Python\Python313\Lib\site-packages\syndicate\core\__init__.py", line 106, in initialize_connection
    CONFIG = ConfigHolder(CONF_PATH)
  File "C:\Users\sunilkumar_pradhan\AppData\Local\Programs\Python\Python313\Lib\site-packages\syndicate\core\conf\processor.py", line 63, in __init__
    self._init_conf_config(dir_path=dir_path)
    ~~~~~~~~~~~~~~~~~~~~~~^^^^^^^^^^^^^^^^^^^
  File "C:\Users\sunilkumar_pradhan\AppData\Local\Programs\Python\Python313\Lib\site-packages\syndicate\core\conf\processor.py", line 92, in _init_conf_config
    raise AssertionError(
        'sdct.conf does not exist inside %s folder' % dir_path)
AssertionError: sdct.conf does not exist inside C:\Users\sunilkumar_pradhan\Desktop\PBE\carrent\backend\.syndicate-config-dev folder
Traceback (most recent call last):
  File "C:\Users\sunilkumar_pradhan\AppData\Local\Programs\Python\Python313\Lib\site-packages\syndicate\core\decorators.py", line 134, in wrapper
    return_code = func(*args, **kwargs)
  File "C:\Users\sunilkumar_pradhan\AppData\Local\Programs\Python\Python313\Lib\site-packages\syndicate\core\handlers.py", line 107, in syndicate
    initialize_connection()
    ~~~~~~~~~~~~~~~~~~~~~^^
  File "C:\Users\sunilkumar_pradhan\AppData\Local\Programs\Python\Python313\Lib\site-packages\syndicate\core\__init__.py", line 106, in initialize_connection
    CONFIG = ConfigHolder(CONF_PATH)
  File "C:\Users\sunilkumar_pradhan\AppData\Local\Programs\Python\Python313\Lib\site-packages\syndicate\core\conf\processor.py", line 63, in __init__
    self._init_conf_config(dir_path=dir_path)
    ~~~~~~~~~~~~~~~~~~~~~~^^^^^^^^^^^^^^^^^^^
  File "C:\Users\sunilkumar_pradhan\AppData\Local\Programs\Python\Python313\Lib\site-packages\syndicate\core\conf\processor.py", line 92, in _init_conf_config
    raise AssertionError(
        'sdct.conf does not exist inside %s folder' % dir_path)
AssertionError: sdct.conf does not exist inside C:\Users\sunilkumar_pradhan\Desktop\PBE\carrent\backend\.syndicate-config-dev folder
2025-05-02 15:36:52,112 [INFO] USER:SunilKumarPradhan handlers.py:106:syndicate LOG: Configuration used: C:\Users\sunilkumar_pradhan\Desktop\PBE\carrent\backend\.syndicate-config-dev
2025-05-02 15:36:52,113 [ERROR] USER:SunilKumarPradhan decorators.py:136:wrapper LOG: sdct.conf does not exist inside C:\Users\sunilkumar_pradhan\Desktop\PBE\carrent\backend\.syndicate-config-dev folder
2025-05-02 15:36:52,117 [ERROR] USER:SunilKumarPradhan decorators.py:137:wrapper LOG: Traceback (most recent call last):
  File "C:\Users\sunilkumar_pradhan\AppData\Local\Programs\Python\Python313\Lib\site-packages\syndicate\core\decorators.py", line 134, in wrapper
    return_code = func(*args, **kwargs)
  File "C:\Users\sunilkumar_pradhan\AppData\Local\Programs\Python\Python313\Lib\site-packages\syndicate\core\handlers.py", line 107, in syndicate
    initialize_connection()
    ~~~~~~~~~~~~~~~~~~~~~^^
  File "C:\Users\sunilkumar_pradhan\AppData\Local\Programs\Python\Python313\Lib\site-packages\syndicate\core\__init__.py", line 106, in initialize_connection
    CONFIG = ConfigHolder(CONF_PATH)
  File "C:\Users\sunilkumar_pradhan\AppData\Local\Programs\Python\Python313\Lib\site-packages\syndicate\core\conf\processor.py", line 63, in __init__
    self._init_conf_config(dir_path=dir_path)
    ~~~~~~~~~~~~~~~~~~~~~~^^^^^^^^^^^^^^^^^^^
  File "C:\Users\sunilkumar_pradhan\AppData\Local\Programs\Python\Python313\Lib\site-packages\syndicate\core\conf\processor.py", line 92, in _init_conf_config
    raise AssertionError(
        'sdct.conf does not exist inside %s folder' % dir_path)
AssertionError: sdct.conf does not exist inside C:\Users\sunilkumar_pradhan\Desktop\PBE\carrent\backend\.syndicate-config-dev folder
Traceback (most recent call last):
  File "C:\Users\sunilkumar_pradhan\AppData\Local\Programs\Python\Python313\Lib\site-packages\syndicate\core\decorators.py", line 134, in wrapper
    return_code = func(*args, **kwargs)
  File "C:\Users\sunilkumar_pradhan\AppData\Local\Programs\Python\Python313\Lib\site-packages\syndicate\core\handlers.py", line 107, in syndicate
    initialize_connection()
    ~~~~~~~~~~~~~~~~~~~~~^^
  File "C:\Users\sunilkumar_pradhan\AppData\Local\Programs\Python\Python313\Lib\site-packages\syndicate\core\__init__.py", line 106, in initialize_connection
    CONFIG = ConfigHolder(CONF_PATH)
  File "C:\Users\sunilkumar_pradhan\AppData\Local\Programs\Python\Python313\Lib\site-packages\syndicate\core\conf\processor.py", line 63, in __init__
    self._init_conf_config(dir_path=dir_path)
    ~~~~~~~~~~~~~~~~~~~~~~^^^^^^^^^^^^^^^^^^^
  File "C:\Users\sunilkumar_pradhan\AppData\Local\Programs\Python\Python313\Lib\site-packages\syndicate\core\conf\processor.py", line 92, in _init_conf_config
    raise AssertionError(
        'sdct.conf does not exist inside %s folder' % dir_path)
AssertionError: sdct.conf does not exist inside C:\Users\sunilkumar_pradhan\Desktop\PBE\carrent\backend\.syndicate-config-dev folder
2025-05-02 15:38:13,927 [INFO] USER:SunilKumarPradhan s3_resource.py:40:validate_bucket_name LOG: Starting validating bucket name 'team03backendbucket'
2025-05-02 15:38:13,927 [INFO] USER:SunilKumarPradhan s3_resource.py:73:validate_bucket_name LOG: Finished validating bucket name 'team03backendbucket'
2025-05-02 15:38:13,928 [WARNING] USER:SunilKumarPradhan generator.py:56:generate_configuration_files LOG: Access_key and secret_key weren't passed. Attempting to load them
2025-05-02 15:38:16,705 [WARNING] USER:SunilKumarPradhan generator.py:76:generate_configuration_files LOG: The config_path property is not specified. The working directory is used
2025-05-02 15:38:16,707 [ERROR] USER:SunilKumarPradhan __init__.py:44:_mkdir LOG: [WinError 183] Cannot create a file when that file already exists: 'C:\\Users\\sunilkumar_pradhan\\Desktop\\PBE\\carrent\\backend\\car-rent-backend\\.syndicate-config-dev'
2025-05-02 15:38:16,733 [WARNING] USER:SunilKumarPradhan generator.py:93:generate_configuration_files LOG: The "project_path" property is not specified. The working directory will be used as a project path. To change the path, edit the syndicate.yml by path C:\Users\sunilkumar_pradhan\Desktop\PBE\carrent\backend\car-rent-backend\.syndicate-config-dev
2025-05-02 15:38:16,745 [INFO] USER:SunilKumarPradhan generator.py:155:generate_configuration_files LOG: Syndicate initialization has been completed. 
Set SDCT_CONF:
Unix: export SDCT_CONF="C:\Users\sunilkumar_pradhan\Desktop\PBE\carrent\backend\car-rent-backend\.syndicate-config-dev"
Windows: setx SDCT_CONF C:\Users\sunilkumar_pradhan\Desktop\PBE\carrent\backend\car-rent-backend\.syndicate-config-dev
2025-05-02 15:38:16,761 [INFO] USER:SunilKumarPradhan helper.py:330:timed LOG: Stage config, elapsed time: 0:00:02.833546
